<!--
 * @Descripttion: 
 * @version: 
 * @Author: LiuZhiYi
 * @Date: 2023-08-13 11:15:49
 * @LastEditTime: 2023-08-13 13:25:11
-->
# 协程
## 组成部分
- promise object：从协程内部操作；协程通过这个object提交结果或异常
- coroutine handle：从协程外部操作，这是一个非拥有句柄，用于恢复协程的执行或销毁协程帧
- coroutine state：这是内部的、动态分配的存储（除非分配被优化）
## 执行过程
- allocates the coroutine state object using operator new.
- copies all function parameters to the coroutine state: by-value parameters are moved or copied, by-reference parameters remain references 
- calls the constructor for the promise object. If the promise type has a constructor that takes all coroutine parameters, that constructor is called, with post-copy coroutine arguments. Otherwise the default constructor is called.
- calls `promise.get_return_object()` and keeps the result in a local variable. The result of that call will be returned to the caller when the coroutine **first suspends**. Any exceptions thrown up to and including this step propagate back to the caller, not placed in the promise.
- calls `promise.initial_suspend()` and co_awaits its result. Typical Promise types either return a `std::suspend_always`, for lazily-started coroutines, or `std::suspend_never`, for eagerly-started coroutines.
- when co_await `promise.initial_suspend()` resumes, starts executing the body of the coroutine.
## awaiter
- 实现`await_ready`, `await_suspend`和`await_resume`；库中实现了两个awaiter，`suspend_always`和`suspend_never`
- 如果`await_ready`返回*false*，进入`await_suspend`函数，挂起当前协程
- `await_resume`协程恢复执行
## co_await
- 挂起协程
- if await_suspend returns void, control is immediately returned to the caller/resumer of the current coroutine (this coroutine remains suspended), otherwise
- if await_suspend returns bool,
  - the value true returns control to the caller/resumer of the current coroutine
  - the value false resumes the current coroutine.
- if await_suspend returns a coroutine handle for some other coroutine, that handle is resumed (by a call to handle.resume()) 
- if await_suspend throws an exception, the exception is caught, the coroutine is resumed, and the exception is immediately re-thrown.
- Finally, awaiter.await_resume() is called (whether the coroutine was suspended or not), and **its result is the result of the whole co_await expr expression**.
~~~c++
#include <coroutine>
#include <iostream>
#include <stdexcept>
#include <thread>
 
auto switch_to_new_thread(std::jthread& out)
{
    struct awaitable
    {
        std::jthread* p_out;
        bool await_ready() { return false; }
        void await_suspend(std::coroutine_handle<> h)
        {
            std::jthread& out = *p_out;
            if (out.joinable())
                throw std::runtime_error("Output jthread parameter not empty");
            out = std::jthread([h] { h.resume(); });
            // Potential undefined behavior: accessing potentially destroyed *this
            // std::cout << "New thread ID: " << p_out->get_id() << '\n';
            std::cout << "New thread ID: " << out.get_id() << '\n'; // this is OK
        }
        void await_resume() {}
    };
    return awaitable{&out};
}
 
struct task
{
    struct promise_type
    {
        task get_return_object() { return {}; }
        std::suspend_never initial_suspend() { return {}; }
        std::suspend_never final_suspend() noexcept { return {}; }
        void return_void() {}
        void unhandled_exception() {}
    };
};
 
task resuming_on_new_thread(std::jthread& out)
{
    std::cout << "Coroutine started on thread: " << std::this_thread::get_id() << '\n';
    co_await switch_to_new_thread(out);
    // awaiter destroyed here
    std::cout << "Coroutine resumed on thread: " << std::this_thread::get_id() << '\n';
}
 
int main()
{
    std::jthread out;
    resuming_on_new_thread(out);
}
// Coroutine started on thread: 139972277602112
// New thread ID: 139972267284224
// Coroutine resumed on thread: 139972267284224
~~~

## co_yield
- 返回一个值同时挂起协程
- 相当于`co_await promise.yield_value(expr)`










